# 拼多多笔试

## 第一题
主要考察函数作用域
```JavaScript
function change(person) {
    person.a = 2
    console.log(person)
    // 为什么这里可以让person指向一个新的对象呢？person对象明明是一个const常量
    person = { a: 4 }
    console.log(person)
}

const person = { a: 3 }
change(person)
// console.log(person)
```
上述代码会输出什么？

答案
```txt
{ a: 2 }
```
我原本以为会报错，因为`person = { a: 4 }`这句代码会把`person`指向一个新的对象，而`person`是常量，但是在函数中这居然是允许的。

*解析*：
在函数`change`中，函数内部会创建一个指针指向`person`，因此我们可以通过这个`person`指针修改外部作用域的`person`，但是在函数中，这个指针并不是`const`类型，因此依然可以将其指向一个新的地址。这个我所学的`C++`语言有点冲突，因为在`C++`，函数中的形参也可以是`const`类型的。

## 第二题
```JavaScript
let promise = new Promise((resolve, reject) => {
    console.log("a new promise start");
    reject("my error")
    console.log("a new promise end")
})
console.log(promise)
// 这里 promise.catch执行完毕之后并不改变promise本身
await promise.catch(console.log)
console.log(promise)
await promise
    // 这句catch语句执行完之后会返回一个新的fulfilled状态的promise
    // 相当于 new Promise((resolve, reject) => {})
    .catch(console.log)
    // 由于上面返回一个fulfilled状态的promise，因此catch不执行
    .catch(console.log)
    // 由于promise中并未传值，因此打印undefined
    .then(res => console.log(res))
console.log(promise)
// 这里，打印的瞬间promise时pending状态的，但是点开查看的时候发现状态已经fulfilled的状态了
console.log(promise.catch(console.log))
```
上述代码会输出什么？

答案
```txt
/*
  先打印出来，
  这是因为立即 resolved 的 Promise 是在本轮事件循环的末尾执行，
  总是晚于本轮循环的同步任务
*/
a new promise start
a new promise end
my error
Promise {<rejected>: 'my error'}
my error
undefined
Promise {<rejected>: 'my error'}
Promise {<pending>}[[Prototype]]: Promise[[PromiseState]]: "fulfilled"[[PromiseResult]]: undefined
my error
```

如果把`reject`改成`resolve`呢?
```JavaScript
let promise = new Promise((resolve, reject) => {
    console.log("a new promise start");
    resolve("my resolve")
    console.log("a new promise end")
})
console.log(promise)
// 这里 promise.catch执行完毕之后并不改变promise本身
await promise.catch(console.log)
console.log(promise)
await promise
    // 这句catch语句执行完之后会返回一个新的fulfilled状态的promise
    // 相当于 new Promise((resolve, reject) => {})
    .catch(console.log)
    // 由于上面返回一个fulfilled状态的promise，因此catch不执行
    .catch(console.log)
    // 由于promise中并未传值，因此打印undefined
    .then(res => console.log(res))
console.log(promise)
// 这里，打印的瞬间promise时pending状态的，但是点开查看的时候发现状态已经fulfilled的状态了
console.log(promise.catch(console.log))
```
结果:
```txt
a new promise start
a new promise end
Promise {<fulfilled>: 'my resolve'}
Promise {<fulfilled>: 'my resolve'}
my resolve
Promise {<fulfilled>: 'my resolve'}
Promise {<pending>}[[Prototype]]: Promise[[PromiseState]]: "fulfilled"[[PromiseResult]]: "my resolve"
```
具体解析由读者自行解析。

`promise`进阶
```JavaScript
let promise = new Promise((resolve, reject) => {
    console.log("a new promise start");
    setTimeout(() => reject("error"), 1000)
    console.log("a new promise end")
}); 
console.log(await promise.catch(console.log))
```
结果：发现最后打印的是`undefined`，这说明`await`之后并没有返回一个新的`promise`。
```txt
a new promise start
a new promise end
error
undefined
```

```JavaScript
let promise = new Promise((resolve, reject) => {
    console.log("a new promise start");
    setTimeout(() => {
        return 10;
        reject("error")
        
    }, 1000)
    console.log("a new promise end")
}); 
console.log(await promise.catch(console.log))
console.log(promise)
```
结果：
```txt
a new promise start
a new promise end
```
发现只打印了两行，这是因为这个promise永远不会`resolve`或者`reject`，因为在这之前函数就已经返回了，因此`await`操作会一直等下去。
```JavaScript
console.log(promise)
```
```txt
Promise {<pending>}
```
打印发现果然是`pending`状态。

接下来我们看看`async`与`await`操作。
```JavaScript
let promise = () => new Promise((resolve, reject) => {
    console.log("a new promise start");
    setTimeout(() => {
        resolve("resolved")
    }, 1000)
    console.log("a new promise end")
}).catch(console.log); 
let p;
(async function() {
    p = await promise()
    console.log(p)
})()
```
结果:
```txt
a new promise start
a new promise end
resolved
```

我们发现在执行`resolve`操作后，p拿到了`resolve`的参数，即`resolved`。


```JavaScript
let promise = () => new Promise((resolve, reject) => {
    console.log("a new promise start");
    setTimeout(() => {
        reject("error")
    }, 1000)
    console.log("a new promise end")
}).catch(console.log); 
let p;
(async function() {
    p = await promise()
    console.log(p)
})()
```

结果：
```txt
a new promise start
a new promise end
error
undefined
```
在这里，由于catch返回的是`new Promise((resolve, reject) => {})`，因此后面p的值是`undefined`
可以发现，通过`async`于`await`可以获取到promise返回的值（这里是`undefined`，虽然不知道获取`undefined`有啥意义哈哈哈）。

`Promise.then`方法的返回值问题
```JavaScript
var p1 = Promise.resolve(42)
p1.then((value)=>{
    //第一种情况，返回一个Promise
    return new Promise(function(resolve,rejected){
        resolve(value+1)
    })
    //第二种情况，返回一个值
    return value+2;
    /*
        第三种情况，新建一个promise，使用reslove返回值
        这里resolve的作用域是内层的，和外层无关，因此外层根本就不会返回任何值。
    */
    const p2 = new Promise(function(resolve,rejected){
        resolve(value+3)
    })
    //第四种情况，新建一个promise，使用return返回值
    const p2 = new Promise(function(resolve,rejected){
        return(value+4)
    })
    //第五种情况，没有返回值
    return undefined
}).then((value)=>{
   console.log(value)
})
```

最后在`then`方法里面添加返回值
```JavaScript
let promise = () => new Promise((resolve, reject) => {
    console.log("a new promise start");
    setTimeout(() => {
        resolve("resolved")
    }, 1000)
    console.log("a new promise end")
}).then(res => res); 
let p;
(async function() {
    p = await promise()
    console.log(p)
})()
```

结果：
```txt
a new promise start
a new promise end
resolved
```

我们发现，在`then`里面返回值，其`return`的值是可以被外界拿到的。

我们在看一下`promise`内部构造函数是否会处理`return`的值
```JavaScript
let promise = new Promise((resolve, reject) => {
    console.log("a new promise start");
        return 1;
    console.log("a new promise end")
}); 
promise.then(console.log)
```

结果：
```txt
a new promise start
```
由于提前`return`，所以只打印的一句，并且如果直接返回一个`1`的话，并不会执行`then`方法。

在`promise`中，`return`的作用仅仅是让函数提前结束，其返回值并没有实际意义。

## 第三题
请设计一个具有如下功能的函数

相关参数：
* @param asyncFn：异步函数
* @param retryTimes：重新执行次数
* @param timeout：超时时间

要求此函数能够调用`asyncFn`，在超过`timeout`时间之后会重新执行，在`retryTimes`次数之后返回失败。

```JavaScript
function fn() {
    return new Promise((resolve, reject) => {
        let rd = Math.random()
        if (rd < 0.5) {
            setTimeout(() => {
                console.log("inner success")
                resolve("success")
            }, 5000 * Math.random())
        } else {
            setTimeout(() => {
                console.log("inner error")
                reject("fail")
            }, 5000 * Math.random())
        }
    })
}

function asyncFn(fn, retryTimes, timeout = 2500) {
    // write your code here
}

asyncFn(fn, 5, 2500)
```

我的答案：
```JavaScript
function asyncFn(fn, retryTimes, timeout = 2500) {
    let rejectPromise = () => new Promise((resolve, reject) => {
            setTimeout(() => {
                console.log("timeout")
                reject("timeout error")
            }, timeout)
        })

    function retry(t) {
        console.log("正在执行第" + t + "次请求")
        return Promise.race([fn(), rejectPromise()])
            .then((res) => {
                console.log(res)
                return res
            })
            .catch((e) => {
                console.log("第" + t + "次请求失败。" + "错误:" + e)
                if (t == retryTimes)  {
                    console.log("超过限定重连次数")
                    return e
                }
                retry(t + 1)
            })
    }
    return retry(1)
}
```

示例打印结果:
```txt
正在执行第1次请求
// 这个是第1次执行完的rejectPromise
timeout
第1次请求失败。错误:timeout error
正在执行第2次请求
// 这个是第1次执行完的fn
inner success 
// 这个是第2次执行完的rejectPromise
timeout
第2次请求失败。错误:timeout error
正在执行第3次请求
// 这个是第2次执行完的fn
inner error
// 这个是第3次执行完的fn
inner success
success
// 这个是第3次执行完的rejectPromise
timeout
```
可以发现确实实现了功能，同时我们也发现`Promise.race`函数在一个`promise`实例竞速成功之后，另外一个比较慢的`promise`实例依然会执行。

有没有办法可以让我在一个`promise`竞速成功之后使得另外一个`promise`实例也结束呢？

```JavaScript
function asyncFn(fn, retryTimes, timeout = 2500) {
    let rejectPromise = function() {
        let _resolve;
        let promise = new Promise((resolve, reject) => {
            _resolve = resolve;
            setTimeout(() => {
                console.log("timeout")
                reject("timeout error")
            }, timeout)
        })
        return {
            promise,
            _resolve
        }
    } 

    function retry(t) {
        console.log("正在执行第" + t + "次请求")
        
        let { promise, _resolve } = rejectPromise()
        return Promise.race([fn(), promise])
            .then((res) => {
                console.log(res)
                _resolve("竞速失败或者另一请求执行成功")
                console.log(promise)
                return res
            })
            .catch((e) => {
                console.log("第" + t + "次请求失败。" + "错误:" + e)
                if (t == retryTimes)  {
                    console.log("超过限定重连次数")
                    _resolve("竞速失败或者另一请求执行成功")
                    console.log(promise)
                    return e
                }
                retry(t + 1)
            })
    }
    return retry(1)
}

asyncFn(fn, 5, 2500)
```
但是后面我发现`console.log("timeout")`这句语句不论如何都是可以执行的，想想也是，打印语句和`resolve`或者`reject`又有什么关系呢？
但是我们发现确实可以在外部调用`promise`的`resolve`或者`reject`操作，因为`console.log(promise)`这句语句确实让控制台打印出来`fulfilled`状态的`promise`。其实我们应该让`rejectPromise`状态改变之后终止`fn`的，因此终止`rejectPromise`意义不大，具体实现就不写了。

要不是今天拼多多的笔试，我还真没发现`promise`的知识这么多这么杂，哎，多参加大厂笔试还是有好处的。